<?xml version="1.0"?>
<sdf version="1.9">
  <model name="mobile_bot">
    <self_collide>false</self_collide>
    <static>false</static>

    <link name="base_link">
      <pose>0 0 0.11 0 0 0</pose>

      <inertial>
        <mass>8.0</mass>
        <inertia>
          <ixx>0.10</ixx>
          <ixy>0.0</ixy>
          <ixz>0.0</ixz>
          <iyy>0.15</iyy>
          <iyz>0.0</iyz>
          <izz>0.20</izz>
        </inertia>
      </inertial>

      <collision name="base_collision">
        <geometry>
          <box>
            <size>0.42 0.32 0.12</size>
          </box>
        </geometry>
      </collision>

      <visual name="base_visual">
        <geometry>
          <box>
            <size>0.42 0.32 0.12</size>
          </box>
        </geometry>
        <material>
          <ambient>0.1 0.3 0.8 1</ambient>
          <diffuse>0.1 0.3 0.8 1</diffuse>
        </material>
      </visual>
    </link>

    <link name="left_wheel_link">
      <pose>0 0.185 0.05 0 0 0</pose>

      <inertial>
        <mass>0.5</mass>
        <inertia>
          <ixx>0.001</ixx>
          <ixy>0.0</ixy>
          <ixz>0.0</ixz>
          <iyy>0.001</iyy>
          <iyz>0.0</iyz>
          <izz>0.001</izz>
        </inertia>
      </inertial>

      <collision name="left_wheel_collision">
        <pose>0 0 0 1.57079632679 0 0</pose>
        <geometry>
          <cylinder>
            <radius>0.05</radius>
            <length>0.035</length>
          </cylinder>
        </geometry>
        <surface>
          <friction>
            <ode>
              <mu>1.5</mu>
              <mu2>1.5</mu2>
            </ode>
          </friction>
        </surface>
      </collision>

      <visual name="left_wheel_visual">
        <pose>0 0 0 1.57079632679 0 0</pose>
        <geometry>
          <cylinder>
            <radius>0.05</radius>
            <length>0.035</length>
          </cylinder>
        </geometry>
        <material>
          <ambient>0.1 0.1 0.1 1</ambient>
          <diffuse>0.1 0.1 0.1 1</diffuse>
        </material>
      </visual>
    </link>

    <joint name="left_wheel_joint" type="revolute">
      <parent>base_link</parent>
      <child>left_wheel_link</child>
      <axis>
        <xyz>0 1 0</xyz>
        <limit>
          <effort>20</effort>
          <velocity>50</velocity>
        </limit>
      </axis>
    </joint>

    <link name="right_wheel_link">
      <pose>0 -0.185 0.05 0 0 0</pose>

      <inertial>
        <mass>0.5</mass>
        <inertia>
          <ixx>0.001</ixx>
          <ixy>0.0</ixy>
          <ixz>0.0</ixz>
          <iyy>0.001</iyy>
          <iyz>0.0</iyz>
          <izz>0.001</izz>
        </inertia>
      </inertial>

      <collision name="right_wheel_collision">
        <pose>0 0 0 1.57079632679 0 0</pose>
        <geometry>
          <cylinder>
            <radius>0.05</radius>
            <length>0.035</length>
          </cylinder>
        </geometry>
        <surface>
          <friction>
            <ode>
              <mu>1.5</mu>
              <mu2>1.5</mu2>
            </ode>
          </friction>
        </surface>
      </collision>

      <visual name="right_wheel_visual">
        <pose>0 0 0 1.57079632679 0 0</pose>
        <geometry>
          <cylinder>
            <radius>0.05</radius>
            <length>0.035</length>
          </cylinder>
        </geometry>
        <material>
          <ambient>0.1 0.1 0.1 1</ambient>
          <diffuse>0.1 0.1 0.1 1</diffuse>
        </material>
      </visual>
    </link>

    <joint name="right_wheel_joint" type="revolute">
      <parent>base_link</parent>
      <child>right_wheel_link</child>
      <axis>
        <xyz>0 1 0</xyz>
        <limit>
          <effort>20</effort>
          <velocity>50</velocity>
        </limit>
      </axis>
    </joint>

    <link name="caster_link">
      <pose>-0.16 0 0.03 0 0 0</pose>
      <collision name="caster_collision">
        <geometry>
          <sphere>
            <radius>0.03</radius>
          </sphere>
        </geometry>
      </collision>
      <visual name="caster_visual">
        <geometry>
          <sphere>
            <radius>0.03</radius>
          </sphere>
        </geometry>
        <material>
          <ambient>0.6 0.6 0.6 1</ambient>
          <diffuse>0.6 0.6 0.6 1</diffuse>
        </material>
      </visual>
    </link>

    <joint name="caster_joint" type="fixed">
      <parent>base_link</parent>
      <child>caster_link</child>
    </joint>

    <plugin filename="gz-sim-diff-drive-system" name="gz::sim::systems::DiffDrive">
      <left_joint>left_wheel_joint</left_joint>
      <right_joint>right_wheel_joint</right_joint>
      <wheel_separation>0.37</wheel_separation>
      <wheel_radius>0.05</wheel_radius>

      <topic>cmd_vel</topic>
      <odom_topic>odom</odom_topic>
      <frame_id>odom</frame_id>
      <child_frame_id>base_link</child_frame_id>
      <tf_topic>tf</tf_topic>
      <odom_publish_frequency>30</odom_publish_frequency>
    </plugin>

    <plugin filename="gz-sim-joint-state-publisher-system"
            name="gz::sim::systems::JointStatePublisher">
      <topic>joint_states</topic>
      <joint_name>left_wheel_joint</joint_name>
      <joint_name>right_wheel_joint</joint_name>
    </plugin>

  </model>
</sdf>